package meowmel.gtsteam.common.metatileentities.multi.steam.advanced;

import gregtech.api.metatileentity.MetaTileEntity;
import gregtech.api.metatileentity.interfaces.IGregTechTileEntity;
import gregtech.api.metatileentity.multiblock.IMultiblockPart;
import gregtech.api.metatileentity.multiblock.MultiblockAbility;
import gregtech.api.metatileentity.multiblock.ParallelLogicType;
import gregtech.api.metatileentity.multiblock.RecipeMapSteamMultiblockController;
import gregtech.api.pattern.BlockPatternTemplate;
import gregtech.api.pattern.SoftTemplate;
import gregtech.api.pattern.TemplatePool;
import gregtech.api.pattern.casing.CasingDefinition;
import gregtech.api.pattern.casing.DeclarativePatternBuilder;
import gregtech.api.unification.material.Materials;
import gregtech.api.util.tooltips.InformationHandler;
import gregtech.api.util.tooltips.TooltipBuilder;
import gregtech.client.renderer.ICubeRenderer;
import gregtech.client.renderer.texture.Textures;
import gregtech.common.blocks.BlockFireboxCasing;
import gregtech.common.blocks.BlockMetalCasing;
import gregtech.common.blocks.MetaBlocks;
import meowmel.gtsteam.api.recipes.GTSRecipeMaps;
import net.minecraft.block.state.IBlockState;
import net.minecraft.item.ItemStack;
import net.minecraft.util.ResourceLocation;
import net.minecraft.world.World;
import net.minecraftforge.fml.relauncher.Side;
import net.minecraftforge.fml.relauncher.SideOnly;
import org.jetbrains.annotations.NotNull;

import java.util.List;

import static gregtech.api.util.RelativeDirection.*;
import static gregtech.client.renderer.texture.Textures.BRONZE_PLATED_BRICKS;
import static gregtech.common.blocks.BlockBoilerCasing.BoilerCasingType.BRONZE_PIPE;

public class MetaTileEntitySteamBiomimeticFactory extends RecipeMapSteamMultiblockController {

    private static final int PARALLEL_LIMIT = 32768;
    private static final SoftTemplate TEMPLATE = TemplatePool.getInstance().register("gtsteam:steam_biomimetic_factory", () ->
            DeclarativePatternBuilder.start(RIGHT, FRONT, UP)

                    .aisle("                                 ", "                                 ", "                                 ", "                                 ", "                                 ", "                                 ", "                                 ", "                                 ", "                                 ", "                                 ", "                                 ", "                                 ", "               A A               ", "               A A               ", "               A A               ", "            AAAAAAAAA            ", "               A A               ", "            AAAAAAAAA            ", "               A A               ", "               A A               ", "               A A               ", "                                 ", "                                 ", "                                 ", "                                 ", "                                 ", "                                 ", "                                 ", "                                 ", "                                 ", "                                 ", "                                 ", "                                 ")
                    .aisle("                                 ", "                                 ", "                                 ", "                                 ", "                                 ", "                                 ", "                                 ", "                                 ", "                                 ", "               A A               ", "               A A               ", "               A A               ", "               A A               ", "              BBBBB              ", "             BBABABB             ", "         AAAABAABAABAAAA         ", "             BBBBBBB             ", "         AAAABAABAABAAAA         ", "             BBABABB             ", "              BBBBB              ", "               A A               ", "               A A               ", "               A A               ", "               A A               ", "                                 ", "                                 ", "                                 ", "                                 ", "                                 ", "                                 ", "                                 ", "                                 ", "                                 ")
                    .aisle("                                 ", "                                 ", "                                 ", "                                 ", "                                 ", "                                 ", "                                 ", "               A A               ", "               A A               ", "               A A               ", "                B                ", "                B                ", "             BBBBBBB             ", "            BB     BB            ", "            B  CCC  B            ", "       AAA  B CDDDC B  AAA       ", "          BBB CDDDC BBB          ", "       AAA  B CDDDC B  AAA       ", "            B  CCC  B            ", "            BB     BB            ", "             BBBBBBB             ", "                B                ", "                B                ", "               A A               ", "               A A               ", "               A A               ", "                                 ", "                                 ", "                                 ", "                                 ", "                                 ", "                                 ", "                                 ")
                    .aisle("                                 ", "                                 ", "                                 ", "                                 ", "                                 ", "                                 ", "               A A               ", "               A A               ", "                B                ", "                B                ", "                                 ", "                                 ", "                                 ", "                                 ", "                                 ", "      AA                 AA      ", "        BB             BB        ", "      AA                 AA      ", "                                 ", "                                 ", "                                 ", "                                 ", "                                 ", "                B                ", "                B                ", "               A A               ", "               A A               ", "                                 ", "                                 ", "                                 ", "                                 ", "                                 ", "                                 ")
                    .aisle("                                 ", "                                 ", "                                 ", "                                 ", "                                 ", "               A A               ", "              AAAAA              ", "                B                ", "                D                ", "                D                ", "                                 ", "                                 ", "                                 ", "                                 ", "      A                   A      ", "     AA                   AA     ", "      ABDD             DDBA      ", "     AA                   AA     ", "      A                   A      ", "                                 ", "                                 ", "                                 ", "                                 ", "                D                ", "                D                ", "                B                ", "              AAAAA              ", "               A A               ", "                                 ", "                                 ", "                                 ", "                                 ", "                                 ")
                    .aisle("                                 ", "                                 ", "                                 ", "                                 ", "               A A               ", "               A A               ", "                B                ", "             ECCDCCE             ", "                                 ", "                                 ", "                                 ", "                                 ", "                                 ", "       E                 E       ", "       C                 C       ", "    AA C                 C AA    ", "      BD                 DB      ", "    AA C                 C AA    ", "       C                 C       ", "       E                 E       ", "                                 ", "                                 ", "                                 ", "                                 ", "                                 ", "             ECCDCCE             ", "                B                ", "               A A               ", "               A A               ", "                                 ", "                                 ", "                                 ", "                                 ")
                    .aisle("                                 ", "                                 ", "                                 ", "               A A               ", "              AAAAA              ", "                B                ", "                D                ", "                                 ", "                                 ", "                                 ", "                                 ", "                                 ", "                                 ", "                                 ", "    A                       A    ", "   AA                       AA   ", "    ABD                   DBA    ", "   AA                       AA   ", "    A                       A    ", "                                 ", "                                 ", "                                 ", "                                 ", "                                 ", "                                 ", "                                 ", "                D                ", "                B                ", "              AAAAA              ", "               A A               ", "                                 ", "                                 ", "                                 ")
                    .aisle("                                 ", "                                 ", "               A A               ", "               A A               ", "                B                ", "             ECCDCCE             ", "                                 ", "                                 ", "                                 ", "                                 ", "                                 ", "                                 ", "                                 ", "     E                     E     ", "     C                     C     ", "  AA C                     C AA  ", "    BD                     DB    ", "  AA C                     C AA  ", "     C                     C     ", "     E                     E     ", "                                 ", "                                 ", "                                 ", "                                 ", "                                 ", "                                 ", "                                 ", "             ECCDCCE             ", "                B                ", "               A A               ", "               A A               ", "                                 ", "                                 ")
                    .aisle("                                 ", "                                 ", "               A A               ", "                B                ", "                D                ", "                                 ", "                                 ", "                                 ", "                                 ", "                                 ", "                                 ", "                                 ", "                                 ", "                                 ", "                                 ", "  A                           A  ", "   BD                       DB   ", "  A                           A  ", "                                 ", "                                 ", "                                 ", "                                 ", "                                 ", "                                 ", "                                 ", "                                 ", "                                 ", "                                 ", "                D                ", "                B                ", "               A A               ", "                                 ", "                                 ")
                    .aisle("                                 ", "               A A               ", "               A A               ", "                B                ", "                D                ", "                                 ", "                                 ", "                                 ", "                                 ", "                                 ", "                                 ", "                                 ", "                                 ", "                                 ", "                                 ", " AA                           AA ", "   BD                       DB   ", " AA                           AA ", "                                 ", "                                 ", "                                 ", "                                 ", "                                 ", "                                 ", "                                 ", "                                 ", "                                 ", "                                 ", "                D                ", "                B                ", "               A A               ", "               A A               ", "                                 ")
                    .aisle("                                 ", "               A A               ", "                B                ", "                                 ", "                                 ", "                                 ", "                                 ", "                                 ", "                                 ", "                                 ", "                                 ", "                                 ", "                                 ", "                                 ", "                                 ", " A                             A ", "  B                           B  ", " A                             A ", "                                 ", "                                 ", "                                 ", "                                 ", "                                 ", "                                 ", "                                 ", "                                 ", "                                 ", "                                 ", "                                 ", "                                 ", "                B                ", "               A A               ", "                                 ")
                    .aisle("                                 ", "               A A               ", "                B                ", "                                 ", "                                 ", "                                 ", "                                 ", "                                 ", "                                 ", "                                 ", "                                 ", "                                 ", "                                 ", "                                 ", "                                 ", " A                             A ", "  B                           B  ", " A                             A ", "                                 ", "                                 ", "                                 ", "                                 ", "                                 ", "                                 ", "                                 ", "                                 ", "                                 ", "                                 ", "                                 ", "                                 ", "                B                ", "               A A               ", "                                 ")
                    .aisle("             AAAAAAA             ", "               A A               ", "             BBBBBBB             ", "                                 ", "                                 ", "                                 ", "                                 ", "                                 ", "                                 ", "                                 ", "                                 ", "                                 ", "                                 ", "  B                           B  ", "  B                           B  ", "AAB                           BAA", "  B                           B  ", "AAB                           BAA", "  B                           B  ", "  B                           B  ", "                                 ", "                                 ", "                                 ", "                                 ", "                                 ", "                                 ", "                                 ", "                                 ", "                                 ", "                                 ", "             BBBBBBB             ", "               A A               ", "               A A               ")
                    .aisle("            AAFFFFFAA            ", "              BBBBB              ", "            BB     BB            ", "                                 ", "                                 ", "       E                 E       ", "                                 ", "     E                     E     ", "                                 ", "                                 ", "                                 ", "                                 ", "  B                           B  ", "  B                           B  ", " B                             B ", "AB                             BA", " B                             B ", "AB                             BA", " B                             B ", "  B                           B  ", "  B                           B  ", "                                 ", "                                 ", "                                 ", "                                 ", "     E                     E     ", "                                 ", "       E                 E       ", "                                 ", "                                 ", "            BB     BB            ", "              BBBBB              ", "               A A               ")
                    .aisle("            AFFFFFFFA            ", "             BBABABB             ", "            B  CCC  B            ", "                                 ", "      A                   A      ", "       C                 C       ", "    A                       A    ", "     C                     C     ", "                                 ", "                                 ", "                                 ", "                                 ", "  B                           B  ", " B                             B ", " B                             B ", "AAC                           CAA", " BC                           CB ", "AAC                           CAA", " B                             B ", " B                             B ", "  B                           B  ", "                                 ", "                                 ", "                                 ", "                                 ", "     C                     C     ", "    A                       A    ", "       C                 C       ", "      A                   A      ", "                                 ", "            B  CCC  B            ", "             BBABABB             ", "               A A               ")
                    .aisle("            AFFAAAFFA            ", "         AAAABAABAABAAAA         ", "       AAA  B CDDDC B  AAA       ", "      AA                 AA      ", "     AA                   AA     ", "    AA C                 C AA    ", "   AA                       AA   ", "  AA C                     C AA  ", "  A                           A  ", " AA                           AA ", " A                             A ", " A                             A ", "AAB                           BAA", "AB                             BA", "AAC                           CAA", "AAD                           DAA", "ABD                           DBA", "AAD                           DAA", "AAC                           CAA", "AB                             BA", "AAB                           BAA", " A                             A ", " A                             A ", " AA                           AA ", "  A                           A  ", "  AA C                     C AA  ", "   AA                       AA   ", "    AA C                 C AA    ", "     AA                   AA     ", "      AA                 AA      ", "       AAA  B CDDDC B  AAA       ", "         AAAABAABAABAAAA         ", "            AAAAAAAAA            ")
                    .aisle("            AFFAMAFFA            ", "             BBBBBBB             ", "          BBB CDDDC BBB          ", "        BB             BB        ", "      ABDD             DDBA      ", "      BD                 DB      ", "    ABD                   DBA    ", "    BD                     DB    ", "   BD                       DB   ", "   BD                       DB   ", "  B                           B  ", "  B                           B  ", "  B                           B  ", " B                             B ", " BC                           CB ", "ABD                           DBA", " BD                           DB ", "ABD                           DBA", " BC                           CB ", " B                             B ", "  B                           B  ", "  B                           B  ", "  B                           B  ", "   BD                       DB   ", "   BD                       DB   ", "    BD                     DB    ", "    ABD                   DBA    ", "      BD                 DB      ", "      ABDD             DDBA      ", "        BB             BB        ", "          BBB CDDDC BBB          ", "             BBBBBBB             ", "               A A               ")
                    .aisle("            AFFAAAFFA            ", "         AAAABAABAABAAAA         ", "       AAA  B CDDDC B  AAA       ", "      AA                 AA      ", "     AA                   AA     ", "    AA C                 C AA    ", "   AA                       AA   ", "  AA C                     C AA  ", "  A                           A  ", " AA                           AA ", " A                             A ", " A                             A ", "AAB                           BAA", "AB                             BA", "AAC                           CAA", "AAD                           DAA", "ABD                           DBA", "AAD                           DAA", "AAC                           CAA", "AB                             BA", "AAB                           BAA", " A                             A ", " A                             A ", " AA                           AA ", "  A                           A  ", "  AA C                     C AA  ", "   AA                       AA   ", "    AA C                 C AA    ", "     AA                   AA     ", "      AA                 AA      ", "       AAA  B CDDDC B  AAA       ", "         AAAABAABAABAAAA         ", "            AAAAAAAAA            ")
                    .aisle("            AFFFFFFFA            ", "             BBABABB             ", "            B  CCC  B            ", "                                 ", "      A                   A      ", "       C                 C       ", "    A                       A    ", "     C                     C     ", "                                 ", "                                 ", "                                 ", "                                 ", "  B                           B  ", " B                             B ", " B                             B ", "AAC                           CAA", " BC                           CB ", "AAC                           CAA", " B                             B ", " B                             B ", "  B                           B  ", "                                 ", "                                 ", "                                 ", "                                 ", "     C                     C     ", "    A                       A    ", "       C                 C       ", "      A                   A      ", "                                 ", "            B  CCC  B            ", "             BBABABB             ", "               A A               ")
                    .aisle("            AAFFFFFAA            ", "              BBBBB              ", "            BB     BB            ", "                                 ", "                                 ", "       E                 E       ", "                                 ", "     E                     E     ", "                                 ", "                                 ", "                                 ", "                                 ", "  B                           B  ", "  B                           B  ", " B                             B ", "AB                             BA", " B                             B ", "AB                             BA", " B                             B ", "  B                           B  ", "  B                           B  ", "                                 ", "                                 ", "                                 ", "                                 ", "     E                     E     ", "                                 ", "       E                 E       ", "                                 ", "                                 ", "            BB     BB            ", "              BBBBB              ", "               A A               ")
                    .aisle("             AAAAAAA             ", "               A A               ", "             BBBBBBB             ", "                                 ", "                                 ", "                                 ", "                                 ", "                                 ", "                                 ", "                                 ", "                                 ", "                                 ", "                                 ", "  B                           B  ", "  B                           B  ", "AAB                           BAA", "  B                           B  ", "AAB                           BAA", "  B                           B  ", "  B                           B  ", "                                 ", "                                 ", "                                 ", "                                 ", "                                 ", "                                 ", "                                 ", "                                 ", "                                 ", "                                 ", "             BBBBBBB             ", "               A A               ", "               A A               ")
                    .aisle("                                 ", "               A A               ", "                B                ", "                                 ", "                                 ", "                                 ", "                                 ", "                                 ", "                                 ", "                                 ", "                                 ", "                                 ", "                                 ", "                                 ", "                                 ", " A                             A ", "  B                           B  ", " A                             A ", "                                 ", "                                 ", "                                 ", "                                 ", "                                 ", "                                 ", "                                 ", "                                 ", "                                 ", "                                 ", "                                 ", "                                 ", "                B                ", "               A A               ", "                                 ")
                    .aisle("                                 ", "               A A               ", "                B                ", "                                 ", "                                 ", "                                 ", "                                 ", "                                 ", "                                 ", "                                 ", "                                 ", "                                 ", "                                 ", "                                 ", "                                 ", " A                             A ", "  B                           B  ", " A                             A ", "                                 ", "                                 ", "                                 ", "                                 ", "                                 ", "                                 ", "                                 ", "                                 ", "                                 ", "                                 ", "                                 ", "                                 ", "                B                ", "               A A               ", "                                 ")
                    .aisle("                                 ", "               A A               ", "               A A               ", "                B                ", "                D                ", "                                 ", "                                 ", "                                 ", "                                 ", "                                 ", "                                 ", "                                 ", "                                 ", "                                 ", "                                 ", " AA                           AA ", "   BD                       DB   ", " AA                           AA ", "                                 ", "                                 ", "                                 ", "                                 ", "                                 ", "                                 ", "                                 ", "                                 ", "                                 ", "                                 ", "                D                ", "                B                ", "               A A               ", "               A A               ", "                                 ")
                    .aisle("                                 ", "                                 ", "               A A               ", "                B                ", "                D                ", "                                 ", "                                 ", "                                 ", "                                 ", "                                 ", "                                 ", "                                 ", "                                 ", "                                 ", "                                 ", "  A                           A  ", "   BD                       DB   ", "  A                           A  ", "                                 ", "                                 ", "                                 ", "                                 ", "                                 ", "                                 ", "                                 ", "                                 ", "                                 ", "                                 ", "                D                ", "                B                ", "               A A               ", "                                 ", "                                 ")
                    .aisle("                                 ", "                                 ", "               A A               ", "               A A               ", "                B                ", "             ECCDCCE             ", "                                 ", "                                 ", "                                 ", "                                 ", "                                 ", "                                 ", "                                 ", "     E                     E     ", "     C                     C     ", "  AA C                     C AA  ", "    BD                     DB    ", "  AA C                     C AA  ", "     C                     C     ", "     E                     E     ", "                                 ", "                                 ", "                                 ", "                                 ", "                                 ", "                                 ", "                                 ", "             ECCDCCE             ", "                B                ", "               A A               ", "               A A               ", "                                 ", "                                 ")
                    .aisle("                                 ", "                                 ", "                                 ", "               A A               ", "              AAAAA              ", "                B                ", "                D                ", "                                 ", "                                 ", "                                 ", "                                 ", "                                 ", "                                 ", "                                 ", "    A                       A    ", "   AA                       AA   ", "    ABD                   DBA    ", "   AA                       AA   ", "    A                       A    ", "                                 ", "                                 ", "                                 ", "                                 ", "                                 ", "                                 ", "                                 ", "                D                ", "                B                ", "              AAAAA              ", "               A A               ", "                                 ", "                                 ", "                                 ")
                    .aisle("                                 ", "                                 ", "                                 ", "                                 ", "               A A               ", "               A A               ", "                B                ", "             ECCDCCE             ", "                                 ", "                                 ", "                                 ", "                                 ", "                                 ", "       E                 E       ", "       C                 C       ", "    AA C                 C AA    ", "      BD                 DB      ", "    AA C                 C AA    ", "       C                 C       ", "       E                 E       ", "                                 ", "                                 ", "                                 ", "                                 ", "                                 ", "             ECCDCCE             ", "                B                ", "               A A               ", "               A A               ", "                                 ", "                                 ", "                                 ", "                                 ")
                    .aisle("                                 ", "                                 ", "                                 ", "                                 ", "                                 ", "               A A               ", "              AAAAA              ", "                B                ", "                D                ", "                D                ", "                                 ", "                                 ", "                                 ", "                                 ", "      A                   A      ", "     AA                   AA     ", "      ABDD             DDBA      ", "     AA                   AA     ", "      A                   A      ", "                                 ", "                                 ", "                                 ", "                                 ", "                D                ", "                D                ", "                B                ", "              AAAAA              ", "               A A               ", "                                 ", "                                 ", "                                 ", "                                 ", "                                 ")
                    .aisle("                                 ", "                                 ", "                                 ", "                                 ", "                                 ", "                                 ", "               A A               ", "               A A               ", "                B                ", "                B                ", "                                 ", "                                 ", "                                 ", "                                 ", "                                 ", "      AA                 AA      ", "        BB             BB        ", "      AA                 AA      ", "                                 ", "                                 ", "                                 ", "                                 ", "                                 ", "                B                ", "                B                ", "               A A               ", "               A A               ", "                                 ", "                                 ", "                                 ", "                                 ", "                                 ", "                                 ")
                    .aisle("                                 ", "                                 ", "                                 ", "                                 ", "                                 ", "                                 ", "                                 ", "               A A               ", "               A A               ", "               A A               ", "                B                ", "                B                ", "             BBBBBBB             ", "            BB     BB            ", "            B  CCC  B            ", "       AAA  B CDDDC B  AAA       ", "          BBB CDDDC BBB          ", "       AAA  B CDDDC B  AAA       ", "            B  CCC  B            ", "            BB     BB            ", "             BBBBBBB             ", "                B                ", "                B                ", "               A A               ", "               A A               ", "               A A               ", "                                 ", "                                 ", "                                 ", "                                 ", "                                 ", "                                 ", "                                 ")
                    .aisle("                                 ", "                                 ", "                                 ", "                                 ", "                                 ", "                                 ", "                                 ", "                                 ", "                                 ", "               A A               ", "               A A               ", "               A A               ", "               A A               ", "              BBBBB              ", "             BBABABB             ", "         AAAABAABAABAAAA         ", "             BBBBBBB             ", "         AAAABAABAABAAAA         ", "             BBABABB             ", "              BBBBB              ", "               A A               ", "               A A               ", "               A A               ", "               A A               ", "                                 ", "                                 ", "                                 ", "                                 ", "                                 ", "                                 ", "                                 ", "                                 ", "                                 ")
                    .aisle("                                 ", "                                 ", "                                 ", "                                 ", "                                 ", "                                 ", "                                 ", "                                 ", "                                 ", "                                 ", "                                 ", "                                 ", "               A A               ", "               A A               ", "               A A               ", "            AAAAAAAAA            ", "               A A               ", "            AAAAAAAAA            ", "               A A               ", "               A A               ", "               A A               ", "                                 ", "                                 ", "                                 ", "                                 ", "                                 ", "                                 ", "                                 ", "                                 ", "                                 ", "                                 ", "                                 ", "                                 ")


                    .self('M', MetaTileEntitySteamBiomimeticFactory.class)
                    .casing('F', getCasingState())
                    .hatch(MultiblockAbility.STEAM_IMPORT_ITEMS, 1, 2)
                    .hatch(MultiblockAbility.STEAM_EXPORT_ITEMS, 1, 2)
                    .hatch(MultiblockAbility.STEAM, 1)
                    .where('B', states(getBoilerState()))
                    .where('A', states(getPipeState()))

                    .where('C', states(getFrameState()))
                    .where('D', states(getFrameState()))
                    .where('E', states(getFrameState()))
                    .where('G', states(getFrameState()))

                    .where(' ', any())
                    .buildTemplate()
    );

    public MetaTileEntitySteamBiomimeticFactory(ResourceLocation metaTileEntityId) {
        super(metaTileEntityId, GTSRecipeMaps.BIOMIMETIC_FACTORY_RECIPES, CONVERSION_RATE, ParallelLogicType.MULTIPLY);
        this.recipeMapWorkable.setParallelLimit(PARALLEL_LIMIT);
    }

    private static IBlockState getFrameState() {
        return MetaBlocks.FRAMES.get(Materials.Bronze).getBlock(Materials.Bronze);
    }

    private static IBlockState getBoilerState() {
        return MetaBlocks.BOILER_FIREBOX_CASING.getState(BlockFireboxCasing.FireboxCasingType.BRONZE_FIREBOX);
    }

    private static IBlockState getPipeState() {
        return MetaBlocks.BOILER_CASING.getState(BRONZE_PIPE);
    }

    public static IBlockState getCasingState() {
        return MetaBlocks.METAL_CASING.getState(BlockMetalCasing.MetalCasingType.BRONZE_BRICKS);
    }

    @Override
    public MetaTileEntity createMetaTileEntity(IGregTechTileEntity metaTileEntityHolder) {
        return new MetaTileEntitySteamBiomimeticFactory(metaTileEntityId);
    }

    @Override
    protected @NotNull BlockPatternTemplate createStructureTemplate() {
        return TEMPLATE.get();
    }

    @SideOnly(Side.CLIENT)
    @Override
    public ICubeRenderer getBaseTexture(IMultiblockPart sourcePart) {
        return BRONZE_PLATED_BRICKS;
    }

    @SideOnly(Side.CLIENT)
    @Override
    protected @NotNull ICubeRenderer getFrontOverlay() {
        return Textures.FUSION_REACTOR_OVERLAY;
    }

    @Override
    public boolean hasMaintenanceMechanics() {
        return false;
    }


    @Override
    public void addInformation(ItemStack stack, World player, @NotNull List<String> tooltip,
                               boolean advanced) {
        InformationHandler.topTooltips("创造一颗星球，然后摧毁它！", tooltip);
        super.addInformation(stack, player, tooltip, advanced);
        TooltipBuilder.create().addSteamMachine(PARALLEL_LIMIT).build(this, tooltip);
    }
}