package meowmel.gtsteam.common.metatileentities.multi.steam.advanced;

import gregtech.api.pattern.element.StructureDefinition;

import static gregtech.api.pattern.element.Elements.*;
import gregtech.api.metatileentity.MetaTileEntity;
import gregtech.api.metatileentity.interfaces.IGregTechTileEntity;
import gregtech.api.metatileentity.multiblock.IMultiblockPart;
import gregtech.api.metatileentity.multiblock.MultiblockAbility;
import gregtech.api.metatileentity.multiblock.ParallelLogicType;
import gregtech.api.metatileentity.multiblock.RecipeMapSteamMultiblockController;
import gregtech.api.pattern.TemplatePool;
import gregtech.api.pattern.casing.CasingDefinition;
import gregtech.api.pattern.casing.DeclarativePatternBuilder;
import gregtech.api.recipes.RecipeMaps;
import gregtech.api.unification.material.Materials;
import gregtech.api.util.tooltips.InformationHandler;
import gregtech.api.util.tooltips.TooltipBuilder;
import gregtech.client.renderer.ICubeRenderer;
import gregtech.client.renderer.texture.Textures;
import gregtech.common.blocks.BlockFireboxCasing;
import gregtech.common.blocks.BlockMetalCasing;
import gregtech.common.blocks.MetaBlocks;
import net.minecraft.block.state.IBlockState;
import net.minecraft.item.ItemStack;
import net.minecraft.util.ResourceLocation;
import net.minecraft.world.World;
import net.minecraftforge.fml.relauncher.Side;
import net.minecraftforge.fml.relauncher.SideOnly;
import org.jetbrains.annotations.NotNull;

import java.util.List;

import static gregtech.client.renderer.texture.Textures.BRONZE_PLATED_BRICKS;
import static gregtech.common.blocks.BlockBoilerCasing.BoilerCasingType.BRONZE_PIPE;

public class MetaTileEntitySteamTranscendentPlasmaForge extends RecipeMapSteamMultiblockController {

    private static final int PARALLEL_LIMIT = 32768;
    private static final StructureDefinition<?> DEFINITION = StructureDefinition.getOrBuild("gtsteam:steam_transcendent_plasma_forge", () ->
            DeclarativePatternBuilder.start()
                    .aisle(" NNN   NNN             NNN   NNN ", "                                 ", "                                 ", "                                 ", " NNN   NNN             NNN   NNN ", "                                 ", "                                 ", "                                 ", "                                 ", "                                 ", " NNN   NNN             NNN   NNN ", "                                 ", "                                 ", "                                 ", " NNN   NNN   N     N   NNN   NNN ", "         N   N     N   N         ", "         N   N     N   N         ", "                                 ", "                                 ", "                                 ", "         N   N     N   N         ", "         N   N     N   N         ", "         N   N     N   N         ", "                                 ")
                    .aisle("NbbbN NbbbN    N N    NbbbN NbbbN", " CCC   CCC             CCC   CCC ", " CCC   CCC             CCC   CCC ", " CCC   CCC             CCC   CCC ", "NbbbN NbbbN           NbbbN NbbbN", "  N     N               N     N  ", "  N     N               N     N  ", "                                 ", "  N     N               N     N  ", "  N     N               N     N  ", "NbbbN NbbbN           NbbbN NbbbN", " CCC   CCC             CCC   CCC ", " CCC   CCC             CCC   CCC ", " CCC   CCC   N     N   CCC   CCC ", "NbbbN NbbNCCCb     bCCCNbbN NbbbN", "         bCCCb     bCCCb         ", "         bCCCb     bCCCb         ", "         N   N     N   N         ", "                                 ", "         N   N     N   N         ", "         bCCCb     bCCCb         ", "         bCCCb     bCCCb         ", "         bCCCb     bCCCb         ", "         N   N     N   N         ")
                    .aisle("NbbbN NbbbNNNNNsNsNNNNNbbbN NbbbN", " CbC   CbC             CbC   CbC ", " CbC   CbC             CbC   CbC ", " CbC   CbC             CbC   CbC ", "NbbbN NbbbN           NbbbN NbbbN", " NNN   NNN             NNN   NNN ", " NNN   NNN             NNN   NNN ", "  s     s               s     s  ", " NNN   NNN             NNN   NNN ", " NNN   NNN             NNN   NNN ", "NbbbN NbbbN           NbbbN NbbbN", " CbC   CbC             CbC   CbC ", " CbC   CbC             CbC   CbC ", " CbC   CbC   N     N   CbC   CbC ", "NbbbN NbbNCCCb     bCCCNbbN NbbbN", "  N     sbbbbbNNsNNbbbbbs     N  ", "  N      bCCCb     bCCCb      N  ", "  N      N   N     N   N      N  ", "   s                         s   ", "   s     N   N     N   N     s   ", "    ss   bCCCb     bCCCb   ss    ", "      NNNbbbbbNNsNNbbbbbNNN      ", "         bCCCb     bCCCb         ", "         N   N     N   N         ")
                    .aisle("NbbbNNNbbbN    NbN    NbbbNNNbbbN", " CCCCCCCCC             CCCCCCCCC ", " CCCCCCCCC             CCCCCCCCC ", " CCCCCCCCC             CCCCCCCCC ", "NbbbNNNbbbN           NbbbNNNbbbN", "  N     N               N     N  ", "  N     N               N     N  ", "                                 ", "  N     N               N     N  ", "  N     N               N     N  ", "NbbbNNNbbbN           NbbbNNNbbbN", " CCCCCCCCC             CCCCCCCCC ", " CCCCCCCCC             CCCCCCCCC ", " CCCCCCCCC   N     N   CCCCCCCCC ", "NbbbNNNbbNCCCb     bCCCNbbNNNbbbN", "         bCCCb     bCCCb         ", "         bCCCb     bCCCb         ", "         NCCCN     NCCCN         ", "  s      NCCCN     NCCCN      s  ", "  s      NCCCN     NCCCN      s  ", "         bCCCb     bCCCb         ", "    ss   bCCCb     bCCCb   ss    ", "         bCCCb     bCCCb         ", "         N   N     N   N         ")
                    .aisle(" NNN   NNN     NbN     NNN   NNN ", "   C   C                 C   C   ", "   C   C                 C   C   ", "   C   C                 C   C   ", " NNN   NNN             NNN   NNN ", "                                 ", "                                 ", "                                 ", "                                 ", "                                 ", " NNN   NNN             NNN   NNN ", "   C   C                 C   C   ", "   C   C                 C   C   ", "   C   C                 C   C   ", " NNN   NN    N     N    NN   NNN ", "         N   N     N   N         ", "         NCCCN     NCCCN         ", "                                 ", "                                 ", "                                 ", "  s      NCCCN     NCCCN      s  ", "   s     N   N     N   N     s   ", "         N   N     N   N         ", "                                 ")
                    .aisle("   N   N       NbN       N   N   ", "   C   C                 C   C   ", "   C   C                 C   C   ", "   C   C                 C   C   ", "   N   N                 N   N   ", "                                 ", "                                 ", "                                 ", "                                 ", "                                 ", "   N   N                 N   N   ", "   C   C                 C   C   ", "   C   C                 C   C   ", "   C   C                 C   C   ", "   N   N                 N   N   ", "                                 ", "         NCCCN     NCCCN         ", "                                 ", "                                 ", "                                 ", "  s      NCCCN     NCCCN      s  ", "   s                         s   ", "                                 ", "                                 ")
                    .aisle(" NNN   NNN     NbN     NNN   NNN ", "   C   C                 C   C   ", "   C   C                 C   C   ", "   C   C                 C   C   ", " NNN   NNN             NNN   NNN ", "                                 ", "                                 ", "                                 ", "                                 ", "                                 ", " NNN   NNN             NNN   NNN ", "   C   C                 C   C   ", "   C   C                 C   C   ", "   C   C                 C   C   ", " NNN   NN    N     N    NN   NNN ", "         N   N     N   N         ", "         NCCCN     NCCCN         ", "                                 ", "                                 ", "                                 ", "         NCCCN     NCCCN         ", "  N      N   N     N   N      N  ", "         N   N     N   N         ", "                                 ")
                    .aisle("NbbbNNNbbbN    NbN    NbbbNNNbbbN", " CCCCCCCCC             CCCCCCCCC ", " CCCCCCCCC             CCCCCCCCC ", " CCCCCCCCC             CCCCCCCCC ", "NbbbNNNbbbN           NbbbNNNbbbN", "  N     N               N     N  ", "  N     N               N     N  ", "                                 ", "  N     N               N     N  ", "  N     N               N     N  ", "NbbbNNNbbbN           NbbbNNNbbbN", " CCCCCCCCC             CCCCCCCCC ", " CCCCCCCCC             CCCCCCCCC ", " CCCCCCCCC   N     N   CCCCCCCCC ", "NbbbNNNbbNCCCb     bCCCNbbNNNbbbN", "         bCCCb     bCCCb         ", "         bCCCb     bCCCb         ", "         NCCCN     NCCCN         ", "         NCCCN     NCCCN         ", "         NCCCN     NCCCN         ", "         bCCCb     bCCCb         ", "  N      bCCCb     bCCCb      N  ", "         bCCCb     bCCCb         ", "         N   N     N   N         ")
                    .aisle("NbbbN NbbbNNNNNsNsNNNNNbbbN NbbbN", " CbC   CbC             CbC   CbC ", " CbC   CbC             CbC   CbC ", " CbC   CbC             CbC   CbC ", "NbbbN NbbbN           NbbbN NbbbN", " NNN   NNN             NNN   NNN ", " NNN   NNN             NNN   NNN ", "  s     s               s     s  ", " NNN   NNN             NNN   NNN ", " NNN   NNN             NNN   NNN ", "NbbbN NbbbN           NbbbN NbbbN", " CbC   CbC             CbC   CbC ", " CbC   CbC             CbC   CbC ", " CbC   CbC   N     N   CbC   CbC ", "NbbbN NbbNCCCb     bCCCNbbN NbbbN", "  s     sbbbbbNNsNNbbbbbs     s  ", "         bCCCb     bCCCb         ", "         N   N     N   N         ", "                                 ", "         N   N     N   N         ", "         bCCCb     bCCCb         ", "  N     sbbbbbNNsNNbbbbbs     N  ", "         bCCCb     bCCCb         ", "         N   N     N   N         ")
                    .aisle("NbbbN NbbbN    NbN    NbbbN NbbbN", " CCC   CCC             CCC   CCC ", " CCC   CCC             CCC   CCC ", " CCC   CCC             CCC   CCC ", "NbbbN NbbbN           NbbbN NbbbN", "  N     N               N     N  ", "  N     N               N     N  ", "                                 ", "  N     N               N     N  ", "  N     N               N     N  ", "NbbbN NbbbN           NbbbN NbbbN", " CCC   CCC             CCC   CCC ", " CCC   CCC             CCC   CCC ", " CCC   CCC   N     N   CCC   CCC ", "NNNN   NNNCCCb     bCCCNNN   NNNN", "NbbbN NbbNCCCb     bCCCNbbN NbbbN", "NbbbNNNbbNCCCb     bCCCNbbNNNbbbN", " NNN   NNN   N     N   NNN   NNN ", "   N   N                 N   N   ", " NNN   NNN   N     N   NNN   NNN ", "NbbbNNNbbNCCCb     bCCCNbbNNNbbbN", "NbbbN NbbNCCCb     bCCCNbbN NbbbN", "NbbbN NbbNCCCb     bCCCNbbN NbbbN", " NNN   NNN   N     N   NNN   NNN ")
                    .aisle(" NNN   NNN     NbN     NNN   NNN ", "                                 ", "                                 ", "                                 ", " NNN   NNN             NNN   NNN ", "                                 ", "                                 ", "                                 ", "                                 ", "                                 ", " NNN   NNN             NNN   NNN ", "                                 ", "                                 ", "                                 ", " CCC   CCC   N     N   CCC   CCC ", " CbC   CbC   N     N   CbC   CbC ", " CCCCCCCCC   N     N   CCCCCCCCC ", "   C   C                 C   C   ", "   C   C                 C   C   ", "   C   C                 C   C   ", " CCCCCCCCC   N     N   CCCCCCCCC ", " CbC   CbC   N     N   CbC   CbC ", " CCC   CCC   N     N   CCC   CCC ", "                                 ")
                    .aisle("  N     N      NbN      N     N  ", "                                 ", "                                 ", "                                 ", "                                 ", "                                 ", "                                 ", "                                 ", "                                 ", "                                 ", "                                 ", "                                 ", "                                 ", "                                 ", " CCC   CCC             CCC   CCC ", " CbC   CbC             CbC   CbC ", " CCCCCCCCC             CCCCCCCCC ", "   C   C                 C   C   ", "   C   C                 C   C   ", "   C   C                 C   C   ", " CCCCCCCCC             CCCCCCCCC ", " CbC   CbC             CbC   CbC ", " CCC   CCC             CCC   CCC ", "                                 ")
                    .aisle("  N     N      NbN      N     N  ", "                                 ", "                                 ", "                                 ", "                                 ", "                                 ", "                                 ", "                                 ", "                                 ", "                                 ", "                                 ", "                                 ", "                                 ", "                                 ", " CCC   CCC             CCC   CCC ", " CbC   CbC             CbC   CbC ", " CCCCCCCCC             CCCCCCCCC ", "   C   C                 C   C   ", "   C   C                 C   C   ", "   C   C                 C   C   ", " CCCCCCCCC             CCCCCCCCC ", " CbC   CbC             CbC   CbC ", " CCC   CCC             CCC   CCC ", "                                 ")
                    .aisle("  N     N     NsNsN     N     N  ", "                                 ", "                                 ", "                                 ", "                                 ", "                                 ", "                                 ", "                                 ", "                                 ", "                                 ", "                                 ", "                                 ", "                                 ", " NNN   NNN             NNN   NNN ", "NbbbN NbbbN           NbbbN NbbbN", "NbbbN NbbbN           NbbbN NbbbN", "NbbbNNNbbbN           NbbbNNNbbbN", " NNN   NNN             NNN   NNN ", "   N   N                 N   N   ", " NNN   NNN             NNN   NNN ", "NbbbNNNbbbN           NbbbNNNbbbN", "NbbbN NbbbN           NbbbN NbbbN", "NbbbN NbbbN           NbbbN NbbbN", " NNN   NNN             NNN   NNN ")
                    .aisle("  N     N    NbbbbbN    N     N  ", "                                 ", "                                 ", "                                 ", "                                 ", "                                 ", "                                 ", "                                 ", "                                 ", "                                 ", "                                 ", "                                 ", "                                 ", "                                 ", "                                 ", "  N     N               N     N  ", "                                 ", "                                 ", "                                 ", "                                 ", "                                 ", "  N     N               N     N  ", "                                 ", "                                 ")
                    .aisle(" NsNNNNNsNNNNsbbbbbsNNNNsNNNNNsN ", "                N                ", "                                 ", "                                 ", "                                 ", "                                 ", "                                 ", "                                 ", "                                 ", "                                 ", "                                 ", "                                 ", "                                 ", "                                 ", "                                 ", "  N     N               N     N  ", "                                 ", "                                 ", "                                 ", "                                 ", "                                 ", "  N     N               N     N  ", "                                 ", "                                 ")
                    .aisle("  NbbbbbNbbbbNbbbbbNbbbbNbbbbbN  ", "               NNN               ", "                ~                ", "                                 ", "                                 ", "                                 ", "                                 ", "                                 ", "                                 ", "                                 ", "                                 ", "                                 ", "                                 ", "                                 ", "                                 ", "  s     s               s     s  ", "                                 ", "                                 ", "                                 ", "                                 ", "                                 ", "  s     s               s     s  ", "                                 ", "                                 ")
                    .aisle(" NsNNNNNsNNNNsbbbbbsNNNNsNNNNNsN ", "                N                ", "                                 ", "                                 ", "                                 ", "                                 ", "                                 ", "                                 ", "                                 ", "                                 ", "                                 ", "                                 ", "                                 ", "                                 ", "                                 ", "  N     N               N     N  ", "                                 ", "                                 ", "                                 ", "                                 ", "                                 ", "  N     N               N     N  ", "                                 ", "                                 ")
                    .aisle("  N     N    NbbbbbN    N     N  ", "                                 ", "                                 ", "                                 ", "                                 ", "                                 ", "                                 ", "                                 ", "                                 ", "                                 ", "                                 ", "                                 ", "                                 ", "                                 ", "                                 ", "  N     N               N     N  ", "                                 ", "                                 ", "                                 ", "                                 ", "                                 ", "  N     N               N     N  ", "                                 ", "                                 ")
                    .aisle("  N     N     NsNsN     N     N  ", "                                 ", "                                 ", "                                 ", "                                 ", "                                 ", "                                 ", "                                 ", "                                 ", "                                 ", "                                 ", "                                 ", "                                 ", " NNN   NNN             NNN   NNN ", "NbbbN NbbbN           NbbbN NbbbN", "NbbbN NbbbN           NbbbN NbbbN", "NbbbNNNbbbN           NbbbNNNbbbN", " NNN   NNN             NNN   NNN ", "   N   N                 N   N   ", " NNN   NNN             NNN   NNN ", "NbbbNNNbbbN           NbbbNNNbbbN", "NbbbN NbbbN           NbbbN NbbbN", "NbbbN NbbbN           NbbbN NbbbN", " NNN   NNN             NNN   NNN ")
                    .aisle("  N     N      NbN      N     N  ", "                                 ", "                                 ", "                                 ", "                                 ", "                                 ", "                                 ", "                                 ", "                                 ", "                                 ", "                                 ", "                                 ", "                                 ", "                                 ", " CCC   CCC             CCC   CCC ", " CbC   CbC             CbC   CbC ", " CCCCCCCCC             CCCCCCCCC ", "   C   C                 C   C   ", "   C   C                 C   C   ", "   C   C                 C   C   ", " CCCCCCCCC             CCCCCCCCC ", " CbC   CbC             CbC   CbC ", " CCC   CCC             CCC   CCC ", "                                 ")
                    .aisle("  N     N      NbN      N     N  ", "                                 ", "                                 ", "                                 ", "                                 ", "                                 ", "                                 ", "                                 ", "                                 ", "                                 ", "                                 ", "                                 ", "                                 ", "                                 ", " CCC   CCC             CCC   CCC ", " CbC   CbC             CbC   CbC ", " CCCCCCCCC             CCCCCCCCC ", "   C   C                 C   C   ", "   C   C                 C   C   ", "   C   C                 C   C   ", " CCCCCCCCC             CCCCCCCCC ", " CbC   CbC             CbC   CbC ", " CCC   CCC             CCC   CCC ", "                                 ")
                    .aisle(" NNN   NNN     NbN     NNN   NNN ", "                                 ", "                                 ", "                                 ", " NNN   NNN             NNN   NNN ", "                                 ", "                                 ", "                                 ", "                                 ", "                                 ", " NNN   NNN             NNN   NNN ", "                                 ", "                                 ", "                                 ", " CCC   CCC   N     N   CCC   CCC ", " CbC   CbC   N     N   CbC   CbC ", " CCCCCCCCC   N     N   CCCCCCCCC ", "   C   C                 C   C   ", "   C   C                 C   C   ", "   C   C                 C   C   ", " CCCCCCCCC   N     N   CCCCCCCCC ", " CbC   CbC   N     N   CbC   CbC ", " CCC   CCC   N     N   CCC   CCC ", "                                 ")
                    .aisle("NbbbN NbbbN    NbN    NbbbN NbbbN", " CCC   CCC             CCC   CCC ", " CCC   CCC             CCC   CCC ", " CCC   CCC             CCC   CCC ", "NbbbN NbbbN           NbbbN NbbbN", "  N     N               N     N  ", "  N     N               N     N  ", "                                 ", "  N     N               N     N  ", "  N     N               N     N  ", "NbbbN NbbbN           NbbbN NbbbN", " CCC   CCC             CCC   CCC ", " CCC   CCC             CCC   CCC ", " CCC   CCC   N     N   CCC   CCC ", "NNNN   NNNCCCb     bCCCNNN   NNNN", "NbbbN NbbNCCCb     bCCCNbbN NbbbN", "NbbbNNNbbNCCCb     bCCCNbbNNNbbbN", " NNN   NNN   N     N   NNN   NNN ", "   N   N                 N   N   ", " NNN   NNN   N     N   NNN   NNN ", "NbbbNNNbbNCCCb     bCCCNbbNNNbbbN", "NbbbN NbbNCCCb     bCCCNbbN NbbbN", "NbbbN NbbNCCCb     bCCCNbbN NbbbN", " NNN   NNN   N     N   NNN   NNN ")
                    .aisle("NbbbN NbbbNNNNNsNsNNNNNbbbN NbbbN", " CbC   CbC             CbC   CbC ", " CbC   CbC             CbC   CbC ", " CbC   CbC             CbC   CbC ", "NbbbN NbbbN           NbbbN NbbbN", " NNN   NNN             NNN   NNN ", " NNN   NNN             NNN   NNN ", "  s     s               s     s  ", " NNN   NNN             NNN   NNN ", " NNN   NNN             NNN   NNN ", "NbbbN NbbbN           NbbbN NbbbN", " CbC   CbC             CbC   CbC ", " CbC   CbC             CbC   CbC ", " CbC   CbC   N     N   CbC   CbC ", "NbbbN NbbNCCCb     bCCCNbbN NbbbN", "  s     sbbbbbNNsNNbbbbbs     s  ", "         bCCCb     bCCCb         ", "         N   N     N   N         ", "                                 ", "         N   N     N   N         ", "         bCCCb     bCCCb         ", "  N     sbbbbbNNsNNbbbbbs     N  ", "         bCCCb     bCCCb         ", "         N   N     N   N         ")
                    .aisle("NbbbNNNbbbN    NbN    NbbbNNNbbbN", " CCCCCCCCC             CCCCCCCCC ", " CCCCCCCCC             CCCCCCCCC ", " CCCCCCCCC             CCCCCCCCC ", "NbbbNNNbbbN           NbbbNNNbbbN", "  N     N               N     N  ", "  N     N               N     N  ", "                                 ", "  N     N               N     N  ", "  N     N               N     N  ", "NbbbNNNbbbN           NbbbNNNbbbN", " CCCCCCCCC             CCCCCCCCC ", " CCCCCCCCC             CCCCCCCCC ", " CCCCCCCCC   N     N   CCCCCCCCC ", "NbbbNNNbbNCCCb     bCCCNbbNNNbbbN", "         bCCCb     bCCCb         ", "         bCCCb     bCCCb         ", "         NCCCN     NCCCN         ", "         NCCCN     NCCCN         ", "         NCCCN     NCCCN         ", "         bCCCb     bCCCb         ", "  N      bCCCb     bCCCb      N  ", "         bCCCb     bCCCb         ", "         N   N     N   N         ")
                    .aisle(" NNN   NNN     NbN     NNN   NNN ", "   C   C                 C   C   ", "   C   C                 C   C   ", "   C   C                 C   C   ", " NNN   NNN             NNN   NNN ", "                                 ", "                                 ", "                                 ", "                                 ", "                                 ", " NNN   NNN             NNN   NNN ", "   C   C                 C   C   ", "   C   C                 C   C   ", "   C   C                 C   C   ", " NNN   NN    N     N    NN   NNN ", "         N   N     N   N         ", "         NCCCN     NCCCN         ", "                                 ", "                                 ", "                                 ", "         NCCCN     NCCCN         ", "  N      N   N     N   N      N  ", "         N   N     N   N         ", "                                 ")
                    .aisle("   N   N       NbN       N   N   ", "   C   C                 C   C   ", "   C   C                 C   C   ", "   C   C                 C   C   ", "   N   N                 N   N   ", "                                 ", "                                 ", "                                 ", "                                 ", "                                 ", "   N   N                 N   N   ", "   C   C                 C   C   ", "   C   C                 C   C   ", "   C   C                 C   C   ", "   N   N                 N   N   ", "                                 ", "         NCCCN     NCCCN         ", "                                 ", "                                 ", "                                 ", "  s      NCCCN     NCCCN      s  ", "   s                         s   ", "                                 ", "                                 ")
                    .aisle(" NNN   NNN     NbN     NNN   NNN ", "   C   C                 C   C   ", "   C   C                 C   C   ", "   C   C                 C   C   ", " NNN   NNN             NNN   NNN ", "                                 ", "                                 ", "                                 ", "                                 ", "                                 ", " NNN   NNN             NNN   NNN ", "   C   C                 C   C   ", "   C   C                 C   C   ", "   C   C                 C   C   ", " NNN   NN    N     N    NN   NNN ", "         N   N     N   N         ", "         NCCCN     NCCCN         ", "                                 ", "                                 ", "                                 ", "  s      NCCCN     NCCCN      s  ", "   s     N   N     N   N     s   ", "         N   N     N   N         ", "                                 ")
                    .aisle("NbbbNNNbbbN    NbN    NbbbNNNbbbN", " CCCCCCCCC             CCCCCCCCC ", " CCCCCCCCC             CCCCCCCCC ", " CCCCCCCCC             CCCCCCCCC ", "NbbbNNNbbbN           NbbbNNNbbbN", "  N     N               N     N  ", "  N     N               N     N  ", "                                 ", "  N     N               N     N  ", "  N     N               N     N  ", "NbbbNNNbbbN           NbbbNNNbbbN", " CCCCCCCCC             CCCCCCCCC ", " CCCCCCCCC             CCCCCCCCC ", " CCCCCCCCC   N     N   CCCCCCCCC ", "NbbbNNNbbNCCCb     bCCCNbbNNNbbbN", "         bCCCb     bCCCb         ", "         bCCCb     bCCCb         ", "         NCCCN     NCCCN         ", "  s      NCCCN     NCCCN      s  ", "  s      NCCCN     NCCCN      s  ", "         bCCCb     bCCCb         ", "    ss   bCCCb     bCCCb   ss    ", "         bCCCb     bCCCb         ", "         N   N     N   N         ")
                    .aisle("NbbbN NbbbNNNNNsNsNNNNNbbbN NbbbN", " CbC   CbC             CbC   CbC ", " CbC   CbC             CbC   CbC ", " CbC   CbC             CbC   CbC ", "NbbbN NbbbN           NbbbN NbbbN", " NNN   NNN             NNN   NNN ", " NNN   NNN             NNN   NNN ", "  s     s               s     s  ", " NNN   NNN             NNN   NNN ", " NNN   NNN             NNN   NNN ", "NbbbN NbbbN           NbbbN NbbbN", " CbC   CbC             CbC   CbC ", " CbC   CbC             CbC   CbC ", " CbC   CbC   N     N   CbC   CbC ", "NbbbN NbbNCCCb     bCCCNbbN NbbbN", "  N     sbbbbbNNsNNbbbbbs     N  ", "  N      bCCCb     bCCCb      N  ", "  N      N   N     N   N      N  ", "   s                         s   ", "   s     N   N     N   N     s   ", "    ss   bCCCb     bCCCb   ss    ", "      NNNbbbbbNNsNNbbbbbNNN      ", "         bCCCb     bCCCb         ", "         N   N     N   N         ")
                    .aisle("NbbbN NbbbN    N N    NbbbN NbbbN", " CCC   CCC             CCC   CCC ", " CCC   CCC             CCC   CCC ", " CCC   CCC             CCC   CCC ", "NbbbN NbbbN           NbbbN NbbbN", "  N     N               N     N  ", "  N     N               N     N  ", "                                 ", "  N     N               N     N  ", "  N     N               N     N  ", "NbbbN NbbbN           NbbbN NbbbN", " CCC   CCC             CCC   CCC ", " CCC   CCC             CCC   CCC ", " CCC   CCC   N     N   CCC   CCC ", "NbbbN NbbNCCCb     bCCCNbbN NbbbN", "         bCCCb     bCCCb         ", "         bCCCb     bCCCb         ", "         N   N     N   N         ", "                                 ", "         N   N     N   N         ", "         bCCCb     bCCCb         ", "         bCCCb     bCCCb         ", "         bCCCb     bCCCb         ", "         N   N     N   N         ")
                    .aisle(" NNN   NNN             NNN   NNN ", "                                 ", "                                 ", "                                 ", " NNN   NNN             NNN   NNN ", "                                 ", "                                 ", "                                 ", "                                 ", "                                 ", " NNN   NNN             NNN   NNN ", "                                 ", "                                 ", "                                 ", " NNN   NNN   N     N   NNN   NNN ", "         N   N     N   N         ", "         N   N     N   N         ", "                                 ", "                                 ", "                                 ", "         N   N     N   N         ", "         N   N     N   N         ", "         N   N     N   N         ", "                                 ")
                    .self('~', MetaTileEntitySteamTranscendentPlasmaForge.class)
                    .where('C', blocks(getFrameState()))
                    .casing('N', getCasingState())
                    .hatch(MultiblockAbility.STEAM_IMPORT_ITEMS, 1, 16)
                    .hatch(MultiblockAbility.STEAM_EXPORT_ITEMS, 1, 16)
                    .hatch(MultiblockAbility.STEAM, 1)
                    .where('b', blocks(getBoilerState()))
                    .where('s', blocks(getPipeState()))
                    .where(' ', any())
                    .buildStructureDefinition()
    );

    public MetaTileEntitySteamTranscendentPlasmaForge(ResourceLocation metaTileEntityId) {
        super(metaTileEntityId, RecipeMaps.FURNACE_RECIPES, CONVERSION_RATE, ParallelLogicType.MULTIPLY);
        this.recipeMapWorkable.setParallelLimit(PARALLEL_LIMIT);
    }

    private static IBlockState getFrameState() {
        return MetaBlocks.FRAMES.get(Materials.Bronze).getBlock(Materials.Bronze);
    }

    private static IBlockState getBoilerState() {
        return MetaBlocks.BOILER_FIREBOX_CASING.getState(BlockFireboxCasing.FireboxCasingType.BRONZE_FIREBOX);
    }

    private static IBlockState getPipeState() {
        return MetaBlocks.BOILER_CASING.getState(BRONZE_PIPE);
    }

    public static IBlockState getCasingState() {
        return MetaBlocks.METAL_CASING.getState(BlockMetalCasing.MetalCasingType.BRONZE_BRICKS);
    }

    @Override
    public MetaTileEntity createMetaTileEntity(IGregTechTileEntity metaTileEntityHolder) {
        return new MetaTileEntitySteamTranscendentPlasmaForge(metaTileEntityId);
    }

    @Override
    protected @NotNull StructureDefinition<?> createStructureDefinition() {
        return DEFINITION;
    }

    @SideOnly(Side.CLIENT)
    @Override
    public ICubeRenderer getBaseTexture(IMultiblockPart sourcePart) {
        return BRONZE_PLATED_BRICKS;
    }

    @SideOnly(Side.CLIENT)
    @Override
    protected @NotNull ICubeRenderer getFrontOverlay() {
        return Textures.FUSION_REACTOR_OVERLAY;
    }

    @Override
    public boolean hasMaintenanceMechanics() {
        return false;
    }


    @Override
    public void addInformation(ItemStack stack, World player, @NotNull List<String> tooltip,
                               boolean advanced) {
        InformationHandler.topTooltips("家用恒星熔炉！燃烧百万物品只需要1克氢！", tooltip);
        super.addInformation(stack, player, tooltip, advanced);
        TooltipBuilder.create().addSteamMachine(PARALLEL_LIMIT).build(this, tooltip);
    }
}